Workbook
Name MinimizeCosts: FALSE
Name TreeData: 'Task 2-4 Decision Tree'!$GH$1001:$GV$1041
Name TreeDiagBase: 'Task 2-4 Decision Tree'!$C$5
Name TreeDiagram: 'Task 2-4 Decision Tree'!$C$5:$U$138
Name UseExpUtility: FALSE

Sheet A2 Text
A1: Assignment 2: Case Problem "Real Estate Development: Select a New Project"
A3: Problem Description
A4: A real estate company is considering the development of one of the following three possible projects: (1) an apartment building; (2) an office building; (3) a warehouse. The amount of payoff (profit) that could be earned by selling the estate depends on the economic conditions, specified as: optimistic, realistic and pessimistic.
A5: The estimated payoffs and probabilities under optimistic, realistic and pessimistic conditions are shown as follows:
A6: Alternatives | B6: States of Nature
B7: Optimistic Conditions | C7: Realistic Conditions | D7: Pessimistic Conditions
A8: Apartment Building | B8: A | C8: B | D8: C
A9: Office Building | B9: D | C9: E | D9: F
A10: Warehouse | B10: G | C10: H | D10: I
A11: Probability | B11: x | C11: y | D11: z
A12: In preparation for a final decision, the company is considering the hiring of a business analyst. If the company hires the analyst, the decision regarding which project to develop will not be made until the analyst presents a survey. However, the analyst is requesting an upfront payment for the survey in the amount of Z. The probabilities of the survey results to be positive or negative are i and k.
A14: Summary tables, in case the company hires a business analyst:
A15: Fee for Survey | B15: Z
A16: Probability of survey results positive | B16: i
A17: Probability of survey results negative | B17: k
A18: (1) If the survey results are positive:
A19: Alternatives | B19: States of Nature
B20: Optimistic Conditions | C20: Realistic Conditions | D20: Pessimistic Conditions
A21: Apartment Building | B21: A - Z | C21: B - Z | D21: C - Z
A22: Office Building | B22: D - Z | C22: E - Z | D22: F - Z
A23: Warehouse | B23: G - Z | C23: H - Z | D23: I - Z
A24: Probability | B24: d | C24: e | D24: f
A25: (2) If the survey results are negative:
A26: Alternatives | B26: States of Nature
B27: Optimistic Conditions | C27: Realistic Conditions | D27: Pessimistic Conditions
A28: Apartment Building | B28: A - Z | C28: B - Z | D28: C - Z
A29: Office Building | B29: D - Z | C29: E - Z | D29: F - Z
A30: Warehouse | B30: G - Z | C30: H - Z | D30: I - Z
A31: Probability | B31: g | C31: h | D31: n
A33: Assignment 2: Starting Conditions
A34: Each student will receive from the instructor an excel file with a different dataset for payoffs (A to I) and probabilities (x,y,z,i,k,d,e,f,g,h,n). You have to prepare and submit a managerial report where you should answer the question: Which one of the development projects should be selected? And based on your estimates, should the company hire the business analyst? | E34: Grading Points Per:
E35: Tasks | F35: Assignment
A36: # | B36: Content per Tasks | F36: 10
A37: Task 2-0 | B37: Students should structure and present their Assignment 2 in the form of a Managerial Report. The expected length of the main body (tasks 2-1 to 2-4) is up to 3 pages APA format, excluding cover page, table of content, executive summary (task 2-5), and appendices (screenshots of the Payoff Table, EMV Table, Sensitivity Analysis Diagram, TreePlan Diagram of the Decision Tree). Submission requirements: Managerial Report (word file), and excel file with completed worksheets (iii) to (vi). | E37: 1
A38: Task 2-1 | B38: Prepare payoff tables and develop a decision tree for this problem (without probabilities and EMVs). | E38: 2
A39: Task 2-2 | B39: Given the probability of all three economic conditions and using expected monetary values (EMVs), calculate EMVs for each node and answer the questions: (1) What's the EMV for not hiring a business analyst and the EMV for hiring a business analyst? (2) What is your recommendation: to hire or not to hire a business analyst? | E39: 2
A40: Task 2-3 | B40: Use sensitivity analysis to define the probability range with respect to the survey results which might affect the decision to hire or not to hire a business analyst, draw the sensitivity chart, and find the probability for their cross point. | E40: 2
A41: Task 2-4 | B41: Apply a software tool for the construction of a decision tree with payoffs, probabilities, and EMVs. The recommended tool is TreePlan: a Microsoft Excel Add-Ins (it is preinstalled on all V-PCs of the MET V-LABs) | E41: 2
A42: Task 2-5 | B42: Prepare an executive summary | E42: 1
B44: List of Worksheets in the Excel File (it should be used as a reference for different tasks of the managerial report)
...

Sheet Payoff Table Template
A1: Alternatives | B1: Optimistic Conditions | C1: Realistic Conditions | D1: Pessimistic Conditions
A2: Apartment Building | B2: 310000 | C2: 190000 | D2: -120000
A3: Office Building | B3: 420000 | C3: 320000 | D3: -80000
A4: Warehouse | B4: 340000 | C4: 210000 | D4: -220000
A5: Probability | B5: 0.36 | C5: 0.52 | D5: 0.12
A7: Fee for Survey | B7: 7000
A8: Probability of survey results positive | B8: 0.54
A9: Probability of survey results negative | B9: 0.46
A11: If the analysis report results positive | B11: Optimistic Conditions | C11: Realistic Conditions | D11: Pessimistic Conditions
A12: probability | B12: 0.5 | C12: 0.37 | D12: 0.13
A14: If the analysis report results negative | B14: Optimistic Conditions | C14: Realistic Conditions | D14: Pessimistic Conditions
A15: probability | B15: 0.13 | C15: 0.3 | D15: 0.57

Sheet Task 2-1 Payoff Table Solution
A1: 1. If the company does not hire a business analyst:
A2: Alternatives | B2: States of Nature
B3: Optimistic Conditions | C3: Realistic Conditions | D3: Pessimistic Conditions
A4: Apartment Building | B4: ='Payoff Table Template'!B2 -> 310000 | C4: ='Payoff Table Template'!C2 -> 190000 | D4: ='Payoff Table Template'!D2 -> -120000
A5: Office Building | B5: ='Payoff Table Template'!B3 -> 420000 | C5: ='Payoff Table Template'!C3 -> 320000 | D5: ='Payoff Table Template'!D3 -> -80000
A6: Warehouse | B6: ='Payoff Table Template'!B4 -> 340000 | C6: ='Payoff Table Template'!C4 -> 210000 | D6: ='Payoff Table Template'!D4 -> -220000
A7: Probability | B7: 0.36 | C7: 0.52 | D7: 0.12
A9: 2. If the company hires a business analyst:
A10: Fee for Survey | B10: ='Payoff Table Template'!B7 -> 7000
A12: 2.1 If the analysis report is positive:
A13: Alternatives | B13: States of Nature
B14: Optimistic Conditions | C14: Realistic Conditions | D14: Pessimistic Conditions
A15: Apartment Building | B15: =B4-$B$10 -> 303000 | C15: =C4-$B$10 -> 183000 | D15: =D4-$B$10 -> -127000
A16: Office Building | B16: =B5-$B$10 -> 413000 | C16: =C5-$B$10 -> 313000 | D16: =D5-$B$10 -> -87000
A17: Warehouse | B17: =B6-$B$10 -> 333000 | C17: =C6-$B$10 -> 203000 | D17: =D6-$B$10 -> -227000
A18: Probability | B18: 0.5 | C18: 0.37 | D18: 0.13
A20: 2.2 If the analysis report is negative:
A21: Alternatives | B21: States of Nature
B22: Optimistic Conditions | C22: Realistic Conditions | D22: Pessimistic Conditions
A23: Apartment Building | B23: =B15 -> 303000 | C23: =C15 -> 183000 | D23: =D15 -> -127000
A24: Office Building | B24: =B16 -> 413000 | C24: =C16 -> 313000 | D24: =D16 -> -87000
A25: Warehouse | B25: =B17 -> 333000 | C25: =C17 -> 203000 | D25: =D17 -> -227000
A26: Probability | B26: 0.13 | C26: 0.3 | D26: 0.57
A28: 3. Sketch of a Decision Tree (without probability and EMVs):

Sheet Task 2-2 Solution
A1: 1. If the company does not hire a business analyst:
A2: Alternatives | B2: States of Nature | E2: EMV | F2: Node
B3: Optimistic Conditions | C3: Realistic Conditions | D3: Pessimistic Conditions
A4: Apartment Building | B4: ='Payoff Table Template'!B2 -> 310000 | C4: ='Payoff Table Template'!C2 -> 190000 | D4: ='Payoff Table Template'!D2 -> -120000 | E4: =B4*$B$7+C4*$C$7+D4*$D$7 -> 196000 | F4: 6
A5: Office Building | B5: ='Payoff Table Template'!B3 -> 420000 | C5: ='Payoff Table Template'!C3 -> 320000 | D5: ='Payoff Table Template'!D3 -> -80000 | E5: =B5*$B$7+C5*$C$7+D5*$D$7 -> 308000 | F5: 7
A6: Warehouse | B6: ='Payoff Table Template'!B4 -> 340000 | C6: ='Payoff Table Template'!C4 -> 210000 | D6: ='Payoff Table Template'!D4 -> -220000 | E6: =B6*$B$7+C6*$C$7+D6*$D$7 -> 205200 | F6: 8
A7: Probability | B7: ='Payoff Table Template'!B5 -> 0.36 | C7: ='Payoff Table Template'!C5 -> 0.52 | D7: ='Payoff Table Template'!D5 -> 0.12
A9: 2. If the company hires a business analyst:
A10: Fee for Survey | B10: ='Payoff Table Template'!B7 -> 7000
A12: 2.1 If the analysis report is positive:
A13: Alternatives | B13: States of Nature | E13: EMV | F13: Node
B14: Optimistic Conditions | C14: Realistic Conditions | D14: Pessimistic Conditions
A15: Apartment Building | B15: ='Task 2-1 Payoff Table Solution'!B15 -> 303000 | C15: ='Task 2-1 Payoff Table Solution'!C15 -> 183000 | D15: ='Task 2-1 Payoff Table Solution'!D15 -> -127000 | E15: =B15*$B$18+C15*$C$18+D15*$D$18 -> 202700 | F15: 9
A16: Office Building | B16: ='Task 2-1 Payoff Table Solution'!B16 -> 413000 | C16: ='Task 2-1 Payoff Table Solution'!C16 -> 313000 | D16: ='Task 2-1 Payoff Table Solution'!D16 -> -87000 | E16: =B16*$B$18+C16*$C$18+D16*$D$18 -> 311000 | F16: 10
A17: Warehouse | B17: ='Task 2-1 Payoff Table Solution'!B17 -> 333000 | C17: ='Task 2-1 Payoff Table Solution'!C17 -> 203000 | D17: ='Task 2-1 Payoff Table Solution'!D17 -> -227000 | E17: =B17*$B$18+C17*$C$18+D17*$D$18 -> 212100 | F17: 11
A18: Probability | B18: ='Task 2-1 Payoff Table Solution'!B18 -> 0.5 | C18: ='Task 2-1 Payoff Table Solution'!C18 -> 0.37 | D18: ='Task 2-1 Payoff Table Solution'!D18 -> 0.13
A20: 2.2 If the analysis report is negative:
A21: Alternatives | B21: States of Nature | E21: EMV | F21: Node
B22: Optimistic Conditions | C22: Realistic Conditions | D22: Pessimistic Conditions
A23: Apartment Building | B23: ='Task 2-1 Payoff Table Solution'!B23 -> 303000 | C23: ='Task 2-1 Payoff Table Solution'!C23 -> 183000 | D23: ='Task 2-1 Payoff Table Solution'!D23 -> -127000 | E23: =B23*$B$26+C23*$C$26+D23*$D$26 -> 21900 | F23: 12
A24: Office Building | B24: ='Task 2-1 Payoff Table Solution'!B24 -> 413000 | C24: ='Task 2-1 Payoff Table Solution'!C24 -> 313000 | D24: ='Task 2-1 Payoff Table Solution'!D24 -> -87000 | E24: =B24*$B$26+C24*$C$26+D24*$D$26 -> 98000 | F24: 13
A25: Warehouse | B25: ='Task 2-1 Payoff Table Solution'!B25 -> 333000 | C25: ='Task 2-1 Payoff Table Solution'!C25 -> 203000 | D25: ='Task 2-1 Payoff Table Solution'!D25 -> -227000 | E25: =B25*$B$26+C25*$C$26+D25*$D$26 -> -25200 | F25: 14
A26: Probability | B26: ='Task 2-1 Payoff Table Solution'!B26 -> 0.13 | C26: ='Task 2-1 Payoff Table Solution'!C26 -> 0.3 | D26: ='Task 2-1 Payoff Table Solution'!D26 -> 0.57
A28: 3. Final Solution
A29: 3.1 EMV (hire a business analyst)
A30: Probability of report results positive | B30: ='Payoff Table Template'!B8 -> 0.54
A31: Probability of report results negative | B31: ='Payoff Table Template'!B9 -> 0.46
C32: Node
A33: EMV (Report results positive) | B33: =E16*B30 -> 167940 | C33: 4
A34: EMV (Report results negative) | B34: =E24*B31 -> 45080 | C34: 5
A35: EMV (Hire a business analyst) | B35: =B33 -> 167940 | C35: 2
A37: 3.2 Final EMV | C37: Node
A38: EMV (Hire a business analyst) | B38: =B35 -> 167940 | C38: 2
A39: EMV (Do not hire a business analyst) | B39: =E5 -> 308000 | C39: 3
A40: Final EMV (Hire/Do not hire a business analyst) | B40: =B39 -> 308000 | C40: 1

Sheet Task 2-3 Solution
D1: +
B2: Alternative | C2: State of Nature
C3: Positive | D3: Negative
B4: Not to hire Business Analyst | C4: ='Task 2-2 Solution'!B39 -> 308000 | D4: =C4 -> 308000
B5: Hire Business Analyst | C5: ='Task 2-2 Solution'!E16 -> 311000 | D5: ='Task 2-2 Solution'!E24 -> 98000
B6: Probability for Senditivity Analysis for hire a business analyst | C6: P | D6: 1-P
C8: EMV(No Analyst)= | D8: 308000
C9: EMV(Analyst)= | D9: 213000*p+98000
B11: P | C11: Not hire | D11: Hire
B12: 0 | C12: =C13 -> 308000 | D12: =D5 -> 98000
B13: 1 | C13: =C4 -> 308000 | D13: =C5 -> 311000
B15: Cross point calculation:
B16: =D4-D5 -> 210000
B17: =B16/213000 -> 0.98591549
B18: p=0.986
B22: When P = 0
B23: EMV(Analyst)=98000
B24: EMV(No Analyst)=311000
B26: When P=1
B27: EMV(Analyst)=167940
B28: EMV(No Analyst)=308000

Sheet Task 2-4 Decision Tree
N5: ='Task 2-1 Payoff Table Solution'!$B$7 -> 0.36
N6: ='Task 2-1 Payoff Table Solution'!$B$3 -> Optimistic Conditions
U7: ='Task 2-2 Solution'!B4 -> 310000
O8: =U7 -> 310000
N10: ='Task 2-1 Payoff Table Solution'!$C$7 -> 0.52
J11: ='Task 2-1 Payoff Table Solution'!$A$4 -> Apartment Building | N11: ='Task 2-1 Payoff Table Solution'!$C$3 -> Realistic Conditions
U12: ='Task 2-2 Solution'!C4 -> 190000
K13: =IF(ABS(1-(N5+N10+N15))<=0.00001,N5*O8+N10*O13+N15*O18,NA()) -> 196000 | O13: =U12 -> 190000
N15: ='Task 2-1 Payoff Table Solution'!$D$7 -> 0.12
N16: ='Task 2-1 Payoff Table Solution'!$D$3 -> Pessimistic Conditions
U17: ='Task 2-2 Solution'!D4 -> -120000
O18: =U17 -> -120000
N20: ='Task 2-1 Payoff Table Solution'!$B$7 -> 0.36
N21: ='Task 2-1 Payoff Table Solution'!$B$3 -> Optimistic Conditions
U22: ='Task 2-2 Solution'!B5 -> 420000
O23: =U22 -> 420000
N25: ='Task 2-1 Payoff Table Solution'!$C$7 -> 0.52
F26: No analyst | J26: ='Task 2-1 Payoff Table Solution'!$A$5 -> Office Building | N26: ='Task 2-1 Payoff Table Solution'!$C$3 -> Realistic Conditions
H27: =IF(G28=K13,1,IF(G28=K28,2,IF(G28=K43,3))) -> 2 | U27: ='Task 2-2 Solution'!C5 -> 320000
G28: =MAX(K13,K28,K43) -> 308000 | K28: =IF(ABS(1-(N20+N25+N30))<=0.00001,N20*O23+N25*O28+N30*O33,NA()) -> 308000 | O28: =U27 -> 320000
N30: ='Task 2-1 Payoff Table Solution'!$D$7 -> 0.12
N31: ='Task 2-1 Payoff Table Solution'!$D$3 -> Pessimistic Conditions
U32: ='Task 2-2 Solution'!D5 -> -80000
O33: =U32 -> -80000
N35: ='Task 2-1 Payoff Table Solution'!$B$7 -> 0.36
N36: ='Task 2-1 Payoff Table Solution'!$B$3 -> Optimistic Conditions
U37: ='Task 2-2 Solution'!B6 -> 340000
O38: =U37 -> 340000
N40: ='Task 2-1 Payoff Table Solution'!$C$7 -> 0.52
J41: ='Task 2-1 Payoff Table Solution'!$A$6 -> Warehouse | N41: ='Task 2-1 Payoff Table Solution'!$C$3 -> Realistic Conditions
U42: ='Task 2-2 Solution'!C6 -> 210000
K43: =IF(ABS(1-(N35+N40+N45))<=0.00001,N35*O38+N40*O43+N45*O48,NA()) -> 205200 | O43: =U42 -> 210000
N45: ='Task 2-1 Payoff Table Solution'!$D$7 -> 0.12
N46: ='Task 2-1 Payoff Table Solution'!$D$3 -> Pessimistic Conditions
U47: ='Task 2-2 Solution'!D6 -> -220000
O48: =U47 -> -220000
R50: ='Task 2-2 Solution'!B18 -> 0.5
R51: ='Task 2-1 Payoff Table Solution'!$B$3 -> Optimistic Conditions
U52: ='Task 2-2 Solution'!B15 -> 303000
S53: =U52 -> 303000
...
